[2023-01-13 10:50:18,800] {taskinstance.py:1035} INFO - Dependencies all met for <TaskInstance: dag_with_python_operator_v4.greet scheduled__2023-01-10T00:00:00+00:00 [queued]>
[2023-01-13 10:50:18,824] {taskinstance.py:1035} INFO - Dependencies all met for <TaskInstance: dag_with_python_operator_v4.greet scheduled__2023-01-10T00:00:00+00:00 [queued]>
[2023-01-13 10:50:18,824] {taskinstance.py:1241} INFO - 
--------------------------------------------------------------------------------
[2023-01-13 10:50:18,824] {taskinstance.py:1242} INFO - Starting attempt 1 of 6
[2023-01-13 10:50:18,824] {taskinstance.py:1243} INFO - 
--------------------------------------------------------------------------------
[2023-01-13 10:50:18,844] {taskinstance.py:1262} INFO - Executing <Task(PythonOperator): greet> on 2023-01-10 00:00:00+00:00
[2023-01-13 10:50:18,850] {standard_task_runner.py:52} INFO - Started process 1358 to run task
[2023-01-13 10:50:18,855] {standard_task_runner.py:76} INFO - Running: ['***', 'tasks', 'run', 'dag_with_python_operator_v4', 'greet', 'scheduled__2023-01-10T00:00:00+00:00', '--job-id', '147', '--raw', '--subdir', 'DAGS_FOLDER/create_dag_with_python_operator.py', '--cfg-path', '/tmp/tmpu7_fq7n8', '--error-file', '/tmp/tmpndxp9so1']
[2023-01-13 10:50:18,856] {standard_task_runner.py:77} INFO - Job 147: Subtask greet
[2023-01-13 10:50:18,896] {logging_mixin.py:109} INFO - Running <TaskInstance: dag_with_python_operator_v4.greet scheduled__2023-01-10T00:00:00+00:00 [running]> on host 75a9b8ab4d7f
[2023-01-13 10:50:18,949] {taskinstance.py:1429} INFO - Exporting the following env vars:
AIRFLOW_CTX_DAG_OWNER=salman
AIRFLOW_CTX_DAG_ID=dag_with_python_operator_v4
AIRFLOW_CTX_TASK_ID=greet
AIRFLOW_CTX_EXECUTION_DATE=2023-01-10T00:00:00+00:00
AIRFLOW_CTX_DAG_RUN_ID=scheduled__2023-01-10T00:00:00+00:00
[2023-01-13 10:50:18,950] {taskinstance.py:1703} ERROR - Task failed with exception
Traceback (most recent call last):
  File "/home/airflow/.local/lib/python3.7/site-packages/airflow/models/taskinstance.py", line 1332, in _run_raw_task
    self._execute_task_with_callbacks(context)
  File "/home/airflow/.local/lib/python3.7/site-packages/airflow/models/taskinstance.py", line 1458, in _execute_task_with_callbacks
    result = self._execute_task(context, self.task)
  File "/home/airflow/.local/lib/python3.7/site-packages/airflow/models/taskinstance.py", line 1514, in _execute_task
    result = execute_callable(context=context)
  File "/home/airflow/.local/lib/python3.7/site-packages/airflow/operators/python.py", line 151, in execute
    return_value = self.execute_callable()
  File "/home/airflow/.local/lib/python3.7/site-packages/airflow/operators/python.py", line 162, in execute_callable
    return self.python_callable(*self.op_args, **self.op_kwargs)
  File "/opt/airflow/dags/create_dag_with_python_operator.py", line 7, in greet
    name = ti.xcoms_pull(task_ids='get_name')
AttributeError: 'TaskInstance' object has no attribute 'xcoms_pull'
[2023-01-13 10:50:18,964] {taskinstance.py:1280} INFO - Marking task as UP_FOR_RETRY. dag_id=dag_with_python_operator_v4, task_id=greet, execution_date=20230110T000000, start_date=20230113T105018, end_date=20230113T105018
[2023-01-13 10:50:18,982] {standard_task_runner.py:91} ERROR - Failed to execute job 147 for task greet
Traceback (most recent call last):
  File "/home/airflow/.local/lib/python3.7/site-packages/airflow/task/task_runner/standard_task_runner.py", line 85, in _start_by_fork
    args.func(args, dag=self.dag)
  File "/home/airflow/.local/lib/python3.7/site-packages/airflow/cli/cli_parser.py", line 48, in command
    return func(*args, **kwargs)
  File "/home/airflow/.local/lib/python3.7/site-packages/airflow/utils/cli.py", line 92, in wrapper
    return f(*args, **kwargs)
  File "/home/airflow/.local/lib/python3.7/site-packages/airflow/cli/commands/task_command.py", line 292, in task_run
    _run_task_by_selected_method(args, dag, ti)
  File "/home/airflow/.local/lib/python3.7/site-packages/airflow/cli/commands/task_command.py", line 107, in _run_task_by_selected_method
    _run_raw_task(args, ti)
  File "/home/airflow/.local/lib/python3.7/site-packages/airflow/cli/commands/task_command.py", line 184, in _run_raw_task
    error_file=args.error_file,
  File "/home/airflow/.local/lib/python3.7/site-packages/airflow/utils/session.py", line 70, in wrapper
    return func(*args, session=session, **kwargs)
  File "/home/airflow/.local/lib/python3.7/site-packages/airflow/models/taskinstance.py", line 1332, in _run_raw_task
    self._execute_task_with_callbacks(context)
  File "/home/airflow/.local/lib/python3.7/site-packages/airflow/models/taskinstance.py", line 1458, in _execute_task_with_callbacks
    result = self._execute_task(context, self.task)
  File "/home/airflow/.local/lib/python3.7/site-packages/airflow/models/taskinstance.py", line 1514, in _execute_task
    result = execute_callable(context=context)
  File "/home/airflow/.local/lib/python3.7/site-packages/airflow/operators/python.py", line 151, in execute
    return_value = self.execute_callable()
  File "/home/airflow/.local/lib/python3.7/site-packages/airflow/operators/python.py", line 162, in execute_callable
    return self.python_callable(*self.op_args, **self.op_kwargs)
  File "/opt/airflow/dags/create_dag_with_python_operator.py", line 7, in greet
    name = ti.xcoms_pull(task_ids='get_name')
AttributeError: 'TaskInstance' object has no attribute 'xcoms_pull'
[2023-01-13 10:50:19,026] {local_task_job.py:154} INFO - Task exited with return code 1
[2023-01-13 10:50:19,059] {local_task_job.py:264} INFO - 0 downstream tasks scheduled from follow-on schedule check
